Workbook

Sheet تقرير الرواتب
A1: تقرير الرواتب عن شهر فبراير 2026
A2: 3 + | B2: الاسم | C2: الفرع | D2: الوظيفة | E2: ساعات العمل | F2: الراتب | G2: الاستحقاق | P2: الاستقطاع | AF2: اجمالى الاستقطاع | AG2: صافى الراتب | AH2: ملاحظات
G3: ايام العمل | H3: قيمة ايام العمل | I3: الاضافى بالساعات | J3: قيمة الاضافى | K3: بدل اجازات | L3: قيمة بدل الاجازات | M3: مكافأة | N3: اخرى | O3: اجمالى الاستحقاق | P3: ساعات التاخير | Q3: قيمة ساعات التأخير | R3: سلف | S3: سلفة مرحله | T3: جزاء ادارى | U3: قيمة الجزاء الادارى | V3: جزاء البصمه | W3: قيمة جزاء البصمه | X3: غياب بدون اذن | Y3: جزاء غياب بدون اذن | Z3: المرضى | AA3: قيمة المرضى | AB3: الراتب التاميني | AC3: تأمينات وضرائب | AD3: الانحرافات | AE3: عجز منتجات& عهدة
A5: 1 | B5: ايه محمد عوضين سليمان | C5: فرع اسماعليه | D5: عضو فريق | E5: 9 | F5: 7000 | G5: 29 | H5: =+F5/30*G5 -> 6766.6667 | I5: 12 | J5: =+I5*F5/30/E5 -> 311.11111 | L5: =+K5*F5/30 -> 0 | O5: =+N5+M5+L5+J5+H5 -> 7077.7778 | Q5: =+F5/30/E5*P5 -> 0 | R5: 1600 | U5: =+F5/30*T5 -> 0 | W5: =+H5/30*V5 -> 0 | Y5: =+F5/30*X5*1 -> 0 | AA5: =+(F5/30*Z5)*0.25 -> 0 | AC5: =AB5*11% -> 0 | AF5: =+AE5+AD5+Y5+U5+R5+Q5+AA5+S5+W5+AC5 -> 1600 | AG5: =+O5-AF5 -> 5477.7778
A6: 3 | B6: نورسين البغدادي ابراهيم سليم | C6: فرع اسماعليه | D6: عضو فريق | E6: 9 | F6: 7000 | G6: 29 | H6: =+F6/30*G6 -> 6766.6667 | I6: 12 | J6: =+I6*F6/30/E6 -> 311.11111 | L6: =+K6*F6/30 -> 0 | O6: =+N6+M6+L6+J6+H6 -> 7077.7778 | Q6: =+F6/30/E6*P6 -> 0 | R6: 500 | U6: =+F6/30*T6 -> 0 | W6: =+H6/30*V6 -> 0 | Y6: =+F6/30*X6*1 -> 0 | AA6: =+(F6/30*Z6)*0.25 -> 0 | AC6: =AB6*11% -> 0 | AF6: =+AE6+AD6+Y6+U6+R6+Q6+AA6+S6+W6+AC6 -> 500 | AG6: =+O6-AF6 -> 6577.7778
A7: 4 | B7: مريم | C7: فرع اسماعليه | D7: كاشير | E7: 9 | F7: 6500 | G7: 30 | H7: =+F7/30*G7 -> 6500 | I7: 10 | J7: =+I7*F7/30/E7 -> 240.74074 | L7: =+K7*F7/30 -> 0 | O7: =+N7+M7+L7+J7+H7 -> 6740.7407 | P7: 6 | Q7: =+F7/30/E7*P7 -> 144.44444 | U7: =+F7/30*T7 -> 0 | W7: =+H7/30*V7 -> 0 | Y7: =+F7/30*X7*1 -> 0 | AA7: =+(F7/30*Z7)*0.25 -> 0 | AC7: =AB7*11% -> 0 | AF7: =+AE7+AD7+Y7+U7+R7+Q7+AA7+S7+W7+AC7 -> 144.44444 | AG7: =+O7-AF7 -> 6596.2963
A8: 5 | B8: سيد احمد حسن جاد الرب | C8: فرع اسماعليه | D8: عضو فريق | E8: 9 | F8: 6000 | G8: 29 | H8: =+F8/30*G8 -> 5800 | I8: 21 | J8: =+I8*F8/30/E8 -> 466.66667 | L8: =+K8*F8/30 -> 0 | O8: =+N8+M8+L8+J8+H8 -> 6266.6667 | P8: 4 | Q8: =+F8/30/E8*P8 -> 88.888889 | R8: 400 | U8: =+F8/30*T8 -> 0 | W8: =+H8/30*V8 -> 0 | Y8: =+F8/30*X8*1 -> 0 | AA8: =+(F8/30*Z8)*0.25 -> 0 | AC8: =AB8*11% -> 0 | AF8: =+AE8+AD8+Y8+U8+R8+Q8+AA8+S8+W8+AC8 -> 488.88889 | AG8: =+O8-AF8 -> 5777.7778 | AH8: تم الغاء الخصم 810ج تحميل اوردر
A9: 6 | B9: احمد رمضان | C9: فرع اسماعليه | D9: عضو فريق | E9: 9 | F9: 6500 | G9: 29 | H9: =+F9/30*G9 -> 6283.3333 | I9: 2 | J9: =+I9*F9/30/E9 -> 48.148148 | L9: =+K9*F9/30 -> 0 | O9: =+N9+M9+L9+J9+H9 -> 6331.4815 | P9: 2 | Q9: =+F9/30/E9*P9 -> 48.148148 | R9: 3300 | T9: 2 | U9: =+F9/30*T9 -> 433.33333 | W9: =+H9/30*V9 -> 0 | Y9: =+F9/30*X9*1 -> 0 | AA9: =+(F9/30*Z9)*0.25 -> 0 | AC9: =AB9*11% -> 0 | AE9: 700 | AF9: =+AE9+AD9+Y9+U9+R9+Q9+AA9+S9+W9+AC9 -> 4481.4815 | AG9: =+O9-AF9 -> 1850 | AH9: 700ج تصليح الزجاج +خصم 2 يوم
A10: 7 | B10: ابراهيم محمود | C10: فرع اسماعليه | D10: عضو فريق | E10: 9 | F10: 6000 | G10: 29 | H10: =+F10/30*G10 -> 5800 | I10: 22 | J10: =+I10*F10/30/E10 -> 488.88889 | L10: =+K10*F10/30 -> 0 | O10: =+N10+M10+L10+J10+H10 -> 6288.8889 | Q10: =+F10/30/E10*P10 -> 0 | R10: 400 | U10: =+F10/30*T10 -> 0 | W10: =+H10/30*V10 -> 0 | Y10: =+F10/30*X10*1 -> 0 | AA10: =+(F10/30*Z10)*0.25 -> 0 | AC10: =AB10*11% -> 0 | AF10: =+AE10+AD10+Y10+U10+R10+Q10+AA10+S10+W10+AC10 -> 400 | AG10: =+O10-AF10 -> 5888.8889
A11: 8 | B11: حسن محمد | C11: فرع اسماعليه | D11: ويتر | E11: 9 | F11: 6000 | G11: 26 | H11: =+F11/30*G11 -> 5200 | J11: =+I11*F11/30/E11 -> 0 | L11: =+K11*F11/30 -> 0 | O11: =+N11+M11+L11+J11+H11 -> 5200 | P11: 7 | Q11: =+F11/30/E11*P11 -> 155.55556 | R11: 1030 | U11: =+F11/30*T11 -> 0 | W11: =+H11/30*V11 -> 0 | X11: 3 | Y11: =+F11/30*X11*1 -> 600 | AA11: =+(F11/30*Z11)*0.25 -> 0 | AC11: =AB11*11% -> 0 | AF11: =+AE11+AD11+Y11+U11+R11+Q11+AA11+S11+W11+AC11 -> 1785.5556 | AG11: =+O11-AF11 -> 3414.4444 | AH11: عدم تنفيذ التعليمات الاداريه المكتوبه + غياب الجمعه
A12: 9 | B12: نها | C12: فرع اسماعليه | D12: كاشير | E12: 9 | F12: 6000 | G12: 29 | H12: =+F12/30*G12 -> 5800 | I12: 4 | J12: =+I12*F12/30/E12 -> 88.888889 | L12: =+K12*F12/30 -> 0 | O12: =+N12+M12+L12+J12+H12 -> 5888.8889 | Q12: =+F12/30/E12*P12 -> 0 | R12: 2210 | U12: =+F12/30*T12 -> 0 | W12: =+H12/30*V12 -> 0 | Y12: =+F12/30*X12*1 -> 0 | AA12: =+(F12/30*Z12)*0.25 -> 0 | AC12: =AB12*11% -> 0 | AF12: =+AE12+AD12+Y12+U12+R12+Q12+AA12+S12+W12+AC12 -> 2210 | AG12: =+O12-AF12 -> 3678.8889
A13: 14 | B13: احمد هادي ابرهيم متولي | C13: فرع اسماعليه | D13: مطبخ | E13: 9 | F13: 10000 | G13: 30 | H13: =+F13/30*G13 -> 10000 | J13: =+I13*F13/30/E13 -> 0 | L13: =+K13*F13/30 -> 0 | M13: 2000 | O13: =+N13+M13+L13+J13+H13 -> 12000 | P13: 3 | Q13: =+F13/30/E13*P13 -> 111.11111 | R13: 3440 | T13: 1 | U13: =+F13/30*T13 -> 333.33333 | W13: =+H13/30*V13 -> 0 | Y13: =+F13/30*X13*1 -> 0 | AA13: =+(F13/30*Z13)*0.25 -> 0 | AC13: =AB13*11% -> 0 | AE13: 175 | AF13: =+AE13+AD13+Y13+U13+R13+Q13+AA13+S13+W13+AC13 -> 4059.4444 | AG13: =+O13-AF13 -> 7940.5556 | AH13: خصم 4 قطع هالك
A14: 15 | B14: مصطفي ابراهيم نبوي دراز | C14: فرع اسماعليه | D14: مدير فرع اسماعيليه | E14: 9 | F14: 10000 | G14: 30 | H14: =+F14/30*G14 -> 10000 | J14: =+I14*F14/30/E14 -> 0 | L14: =+K14*F14/30 -> 0 | M14: 2000 | O14: =+N14+M14+L14+J14+H14 -> 12000 | Q14: =+F14/30/E14*P14 -> 0 | R14: 1600 | U14: =+F14/30*T14 -> 0 | W14: =+H14/30*V14 -> 0 | Y14: =+F14/30*X14*1 -> 0 | AA14: =+(F14/30*Z14)*0.25 -> 0 | AC14: =AB14*11% -> 0 | AF14: =+AE14+AD14+Y14+U14+R14+Q14+AA14+S14+W14+AC14 -> 1600 | AG14: =+O14-AF14 -> 10400
A15: 13 | B15: كريم خالد عبدالمريد دياب محمود | C15: فرع اسماعليه | D15: عضو فريق | E15: 9 | F15: 7500 | G15: 27 | H15: =+F15/30*G15 -> 6750 | J15: =+I15*F15/30/E15 -> 0 | L15: =+K15*F15/30 -> 0 | M15: 2000 | O15: =+N15+M15+L15+J15+H15 -> 8750 | Q15: =+F15/30/E15*P15 -> 0 | R15: 4725 | T15: 2 | U15: =+F15/30*T15 -> 500 | W15: =+H15/30*V15 -> 0 | Y15: =+F15/30*X15*1 -> 0 | AA15: =+(F15/30*Z15)*0.25 -> 0 | AC15: =AB15*11% -> 0 | AF15: =+AE15+AD15+Y15+U15+R15+Q15+AA15+S15+W15+AC15 -> 5225 | AG15: =+O15-AF15 -> 3525 | AH15: التطاول والمشاجرة مع مستر عصام + عم الالتزام بكتابه الحضور
A16: 16 | B16: عبدالرحمن اوتاكا | C16: فرع اسماعليه | D16: كاشير | E16: 9 | F16: 6000 | G16: 21 | H16: =+F16/30*G16 -> 4200 | I16: 10 | J16: =+I16*F16/30/E16 -> 222.22222 | L16: =+K16*F16/30 -> 0 | O16: =+N16+M16+L16+J16+H16 -> 4422.2222 | P16: 2 | Q16: =+F16/30/E16*P16 -> 44.444444 | R16: 635 | U16: =+F16/30*T16 -> 0 | W16: =+H16/30*V16 -> 0 | Y16: =+F16/30*X16*1 -> 0 | AA16: =+(F16/30*Z16)*0.25 -> 0 | AC16: =AB16*11% -> 0 | AF16: =+AE16+AD16+Y16+U16+R16+Q16+AA16+S16+W16+AC16 -> 679.44444 | AG16: =+O16-AF16 -> 3742.7778
A17: 17 | B17: شريف عاطف | C17: فرع اسماعليه | D17: مطبخ | E17: 9 | F17: 10000 | G17: 30 | H17: =+F17/30*G17 -> 10000 | I17: 50 | J17: =+I17*F17/30/E17 -> 1851.8519 | L17: =+K17*F17/30 -> 0 | O17: =+N17+M17+L17+J17+H17 -> 11851.852 | Q17: =+F17/30/E17*P17 -> 0 | R17: 3200 | U17: =+F17/30*T17 -> 0 | W17: =+H17/30*V17 -> 0 | Y17: =+F17/30*X17*1 -> 0 | AA17: =+(F17/30*Z17)*0.25 -> 0 | AC17: =AB17*11% -> 0 | AF17: =+AE17+AD17+Y17+U17+R17+Q17+AA17+S17+W17+AC17 -> 3200 | AG17: =+O17-AF17 -> 8651.8519
A18: 18 | B18: علي رفاعي | C18: فرع اسماعليه | D18: مطبخ | E18: 9 | F18: 8000 | G18: 21 | H18: =+F18/30*G18 -> 5600 | I18: 28 | J18: =+I18*F18/30/E18 -> 829.62963 | L18: =+K18*F18/30 -> 0 | O18: =+N18+M18+L18+J18+H18 -> 6429.6296 | Q18: =+F18/30/E18*P18 -> 0 | R18: 3895 | U18: =+F18/30*T18 -> 0 | W18: =+H18/30*V18 -> 0 | Y18: =+F18/30*X18*1 -> 0 | AA18: =+(F18/30*Z18)*0.25 -> 0 | AC18: =AB18*11% -> 0 | AF18: =+AE18+AD18+Y18+U18+R18+Q18+AA18+S18+W18+AC18 -> 3895 | AG18: =+O18-AF18 -> 2534.6296
A19: 12 | B19: محمد علي عفرتو | C19: فرع اسماعليه | D19: عضو فريق | E19: 9 | F19: 7000 | G19: 29 | H19: =+F19/30*G19 -> 6766.6667 | J19: =+I19*F19/30/E19 -> 0 | L19: =+K19*F19/30 -> 0 | O19: =+N19+M19+L19+J19+H19 -> 6766.6667 | Q19: =+F19/30/E19*P19 -> 0 | R19: 3910 | T19: 1 | U19: =+F19/30*T19 -> 233.33333 | W19: =+H19/30*V19 -> 0 | Y19: =+F19/30*X19*1 -> 0 | AA19: =+(F19/30*Z19)*0.25 -> 0 | AC19: =AB19*11% -> 0 | AE19: 590 | AF19: =+AE19+AD19+Y19+U19+R19+Q19+AA19+S19+W19+AC19 -> 4733.3333 | AG19: =+O19-AF19 -> 2033.3333 | AH19: خصم اوردر مرتجع 590ج + 1 يوم
A20: 11 | B20: عبدالرحمن احمد محمد احمد مصطفي | C20: فرع اسماعليه | D20: كاشير | E20: 9 | F20: 6500 | G20: 13 | H20: =+F20/30*G20 -> 2816.6667 | J20: =+I20*F20/30/E20 -> 0 | L20: =+K20*F20/30 -> 0 | O20: =+N20+M20+L20+J20+H20 -> 2816.6667 | Q20: =+F20/30/E20*P20 -> 0 | R20: 700 | U20: =+F20/30*T20 -> 0 | W20: =+H20/30*V20 -> 0 | Y20: =+F20/30*X20*1 -> 0 | AA20: =+(F20/30*Z20)*0.25 -> 0 | AC20: =AB20*11% -> 0 | AF20: =+AE20+AD20+Y20+U20+R20+Q20+AA20+S20+W20+AC20 -> 700 | AG20: =+O20-AF20 -> 2116.6667
A21: 10 | B21: فادي روماني | C21: فرع اسماعليه | D21: عضو فريق | E21: 9 | F21: 5500 | G21: 7 | H21: =+F21/30*G21 -> 1283.3333 | J21: =+I21*F21/30/E21 -> 0 | L21: =+K21*F21/30 -> 0 | O21: =+N21+M21+L21+J21+H21 -> 1283.3333 | Q21: =+F21/30/E21*P21 -> 0 | U21: =+F21/30*T21 -> 0 | W21: =+H21/30*V21 -> 0 | Y21: =+F21/30*X21*1 -> 0 | AA21: =+(F21/30*Z21)*0.25 -> 0 | AC21: =AB21*11% -> 0 | AF21: =+AE21+AD21+Y21+U21+R21+Q21+AA21+S21+W21+AC21 -> 0 | AG21: =+O21-AF21 -> 1283.3333
A22: 23 | B22: سمير محمد عبدالواحد | C22: فرع اسماعليه | D22: استيوارد | E22: 9 | F22: 4000 | G22: 27 | H22: =+F22/30*G22 -> 3600 | J22: =+I22*F22/30/E22 -> 0 | L22: =+K22*F22/30 -> 0 | O22: =+N22+M22+L22+J22+H22 -> 3600 | Q22: =+F22/30/E22*P22 -> 0 | U22: =+F22/30*T22 -> 0 | W22: =+H22/30*V22 -> 0 | Y22: =+F22/30*X22*1 -> 0 | AA22: =+(F22/30*Z22)*0.25 -> 0 | AC22: =AB22*11% -> 0 | AF22: =+AE22+AD22+Y22+U22+R22+Q22+AA22+S22+W22+AC22 -> 0 | AG22: =+O22-AF22 -> 3600
A23: 24 | B23: زياد محمد عبدالواحد | C23: فرع اسماعليه | D23: استيوارد | E23: 9 | F23: 4000 | G23: 27 | H23: =+F23/30*G23 -> 3600 | J23: =+I23*F23/30/E23 -> 0 | L23: =+K23*F23/30 -> 0 | O23: =+N23+M23+L23+J23+H23 -> 3600 | Q23: =+F23/30/E23*P23 -> 0 | U23: =+F23/30*T23 -> 0 | W23: =+H23/30*V23 -> 0 | Y23: =+F23/30*X23*1 -> 0 | AA23: =+(F23/30*Z23)*0.25 -> 0 | AC23: =AB23*11% -> 0 | AF23: =+AE23+AD23+Y23+U23+R23+Q23+AA23+S23+W23+AC23 -> 0 | AG23: =+O23-AF23 -> 3600
A24: 25 | B24: محمود سيد نصرالله | C24: فرع اسماعليه | D24: عضو فريق | E24: 9 | F24: 5000 | G24: 23 | H24: =+F24/30*G24 -> 3833.3333 | J24: =+I24*F24/30/E24 -> 0 | L24: =+K24*F24/30 -> 0 | O24: =+N24+M24+L24+J24+H24 -> 3833.3333 | Q24: =+F24/30/E24*P24 -> 0 | R24: 500 | T24: 2 | U24: =+F24/30*T24 -> 333.33333 | W24: =+H24/30*V24 -> 0 | Y24: =+F24/30*X24*1 -> 0 | AA24: =+(F24/30*Z24)*0.25 -> 0 | AC24: =AB24*11% -> 0 | AF24: =+AE24+AD24+Y24+U24+R24+Q24+AA24+S24+W24+AC24 -> 833.33333 | AG24: =+O24-AF24 -> 3000
A25: 26 | B25: مروان الراوي | C25: فرع اسماعليه | D25: عضو فريق | E25: 9 | F25: 6000 | G25: 30 | H25: =+F25/30*G25 -> 6000 | I25: 33 | J25: =+I25*F25/30/E25 -> 733.33333 | L25: =+K25*F25/30 -> 0 | O25: =+N25+M25+L25+J25+H25 -> 6733.3333 | P25: 11 | Q25: =+F25/30/E25*P25 -> 244.44444 | R25: 3155 | U25: =+F25/30*T25 -> 0 | W25: =+H25/30*V25 -> 0 | Y25: =+F25/30*X25*1 -> 0 | AA25: =+(F25/30*Z25)*0.25 -> 0 | AC25: =AB25*11% -> 0 | AF25: =+AE25+AD25+Y25+U25+R25+Q25+AA25+S25+W25+AC25 -> 3399.4444 | AG25: =+O25-AF25 -> 3333.8889
A26: 27 | B26: عصام الدرديري | C26: فرع اسماعليه | D26: مدير التشغيل | E26: 9 | F26: 20000 | G26: 30 | H26: =+F26/30*G26 -> 20000 | J26: =+I26*F26/30/E26 -> 0 | L26: =+K26*F26/30 -> 0 | O26: =+N26+M26+L26+J26+H26 -> 20000 | Q26: =+F26/30/E26*P26 -> 0 | R26: 1785 | U26: =+F26/30*T26 -> 0 | W26: =+H26/30*V26 -> 0 | Y26: =+F26/30*X26*1 -> 0 | AA26: =+(F26/30*Z26)*0.25 -> 0 | AC26: =AB26*11% -> 0 | AF26: =+AE26+AD26+Y26+U26+R26+Q26+AA26+S26+W26+AC26 -> 1785 | AG26: =+O26-AF26 -> 18215
A27: 28 | B27: يوسف محمد | C27: فرع اسماعليه | D27: استيوارد | E27: 9 | F27: 2000 | G27: 30 | H27: =+F27/30*G27 -> 2000 | J27: =+I27*F27/30/E27 -> 0 | L27: =+K27*F27/30 -> 0 | O27: =+N27+M27+L27+J27+H27 -> 2000 | Q27: =+F27/30/E27*P27 -> 0 | R27: 500 | U27: =+F27/30*T27 -> 0 | W27: =+H27/30*V27 -> 0 | Y27: =+F27/30*X27*1 -> 0 | AA27: =+(F27/30*Z27)*0.25 -> 0 | AC27: =AB27*11% -> 0 | AF27: =+AE27+AD27+Y27+U27+R27+Q27+AA27+S27+W27+AC27 -> 500 | AG27: =+O27-AF27 -> 1500
A28: 29 | E28: 9 | H28: =+F28/30*G28 -> 0 | J28: =+I28*F28/30/E28 -> 0 | L28: =+K28*F28/30 -> 0 | O28: =+N28+M28+L28+J28+H28 -> 0 | Q28: =+F28/30/E28*P28 -> 0 | U28: =+F28/30*T28 -> 0 | W28: =+H28/30*V28 -> 0 | Y28: =+F28/30*X28*1 -> 0 | AA28: =+(F28/30*Z28)*0.25 -> 0 | AC28: =AB28*11% -> 0 | AF28: =+AE28+AD28+Y28+U28+R28+Q28+AA28+S28+W28+AC28 -> 0 | AG28: =+O28-AF28 -> 0
A29: 30 | E29: 9 | H29: =+F29/30*G29 -> 0 | J29: =+I29*F29/30/E29 -> 0 | L29: =+K29*F29/30 -> 0 | O29: =+N29+M29+L29+J29+H29 -> 0 | Q29: =+F29/30/E29*P29 -> 0 | U29: =+F29/30*T29 -> 0 | W29: =+H29/30*V29 -> 0 | Y29: =+F29/30*X29*1 -> 0 | AA29: =+(F29/30*Z29)*0.25 -> 0 | AC29: =AB29*11% -> 0 | AF29: =+AE29+AD29+Y29+U29+R29+Q29+AA29+S29+W29+AC29 -> 0 | AG29: =+O29-AF29 -> 0
A30: 31 | E30: 9 | H30: =+F30/30*G30 -> 0 | J30: =+I30*F30/30/E30 -> 0 | L30: =+K30*F30/30 -> 0 | O30: =+N30+M30+L30+J30+H30 -> 0 | Q30: =+F30/30/E30*P30 -> 0 | U30: =+F30/30*T30 -> 0 | W30: =+H30/30*V30 -> 0 | Y30: =+F30/30*X30*1 -> 0 | AA30: =+(F30/30*Z30)*0.25 -> 0 | AC30: =AB30*11% -> 0 | AF30: =+AE30+AD30+Y30+U30+R30+Q30+AA30+S30+W30+AC30 -> 0 | AG30: =+O30-AF30 -> 0
A31: 32 | E31: 9 | H31: =+F31/30*G31 -> 0 | J31: =+I31*F31/30/E31 -> 0 | L31: =+K31*F31/30 -> 0 | O31: =+N31+M31+L31+J31+H31 -> 0 | Q31: =+F31/30/E31*P31 -> 0 | U31: =+F31/30*T31 -> 0 | W31: =+H31/30*V31 -> 0 | Y31: =+F31/30*X31*1 -> 0 | AA31: =+(F31/30*Z31)*0.25 -> 0 | AC31: =AB31*11% -> 0 | AF31: =+AE31+AD31+Y31+U31+R31+Q31+AA31+S31+W31+AC31 -> 0 | AG31: =+O31-AF31 -> 0
A32: 33 | E32: 9 | H32: =+F32/30*G32 -> 0 | J32: =+I32*F32/30/E32 -> 0 | L32: =+K32*F32/30 -> 0 | O32: =+N32+M32+L32+J32+H32 -> 0 | Q32: =+F32/30/E32*P32 -> 0 | U32: =+F32/30*T32 -> 0 | W32: =+H32/30*V32 -> 0 | Y32: =+F32/30*X32*1 -> 0 | AA32: =+(F32/30*Z32)*0.25 -> 0 | AC32: =AB32*11% -> 0 | AF32: =+AE32+AD32+Y32+U32+R32+Q32+AA32+S32+W32+AC32 -> 0 | AG32: =+O32-AF32 -> 0
A33: 34 | E33: 9 | H33: =+F33/30*G33 -> 0 | J33: =+I33*F33/30/E33 -> 0 | L33: =+K33*F33/30 -> 0 | O33: =+N33+M33+L33+J33+H33 -> 0 | Q33: =+F33/30/E33*P33 -> 0 | U33: =+F33/30*T33 -> 0 | W33: =+H33/30*V33 -> 0 | Y33: =+F33/30*X33*1 -> 0 | AA33: =+(F33/30*Z33)*0.25 -> 0 | AC33: =AB33*11% -> 0 | AF33: =+AE33+AD33+Y33+U33+R33+Q33+AA33+S33+W33+AC33 -> 0 | AG33: =+O33-AF33 -> 0
A34: 35 | E34: 9 | H34: =+F34/30*G34 -> 0 | J34: =+I34*F34/30/E34 -> 0 | L34: =+K34*F34/30 -> 0 | O34: =+N34+M34+L34+J34+H34 -> 0 | Q34: =+F34/30/E34*P34 -> 0 | U34: =+F34/30*T34 -> 0 | W34: =+H34/30*V34 -> 0 | Y34: =+F34/30*X34*1 -> 0 | AA34: =+(F34/30*Z34)*0.25 -> 0 | AC34: =AB34*11% -> 0 | AF34: =+AE34+AD34+Y34+U34+R34+Q34+AA34+S34+W34+AC34 -> 0 | AG34: =+O34-AF34 -> 0
A35: 36 | E35: 9 | H35: =+F35/30*G35 -> 0 | J35: =+I35*F35/30/E35 -> 0 | L35: =+K35*F35/30 -> 0 | O35: =+N35+M35+L35+J35+H35 -> 0 | Q35: =+F35/30/E35*P35 -> 0 | U35: =+F35/30*T35 -> 0 | W35: =+H35/30*V35 -> 0 | Y35: =+F35/30*X35*1 -> 0 | AA35: =+(F35/30*Z35)*0.25 -> 0 | AC35: =AB35*11% -> 0 | AF35: =+AE35+AD35+Y35+U35+R35+Q35+AA35+S35+W35+AC35 -> 0 | AG35: =+O35-AF35 -> 0
A36: 37 | E36: 9 | H36: =+F36/30*G36 -> 0 | J36: =+I36*F36/30/E36 -> 0 | L36: =+K36*F36/30 -> 0 | O36: =+N36+M36+L36+J36+H36 -> 0 | Q36: =+F36/30/E36*P36 -> 0 | U36: =+F36/30*T36 -> 0 | W36: =+H36/30*V36 -> 0 | Y36: =+F36/30*X36*1 -> 0 | AA36: =+(F36/30*Z36)*0.25 -> 0 | AC36: =AB36*11% -> 0 | AF36: =+AE36+AD36+Y36+U36+R36+Q36+AA36+S36+W36+AC36 -> 0 | AG36: =+O36-AF36 -> 0
A37: 38 | E37: 9 | H37: =+F37/30*G37 -> 0 | J37: =+I37*F37/30/E37 -> 0 | L37: =+K37*F37/30 -> 0 | O37: =+N37+M37+L37+J37+H37 -> 0 | Q37: =+F37/30/E37*P37 -> 0 | U37: =+F37/30*T37 -> 0 | W37: =+H37/30*V37 -> 0 | Y37: =+F37/30*X37*1 -> 0 | AA37: =+(F37/30*Z37)*0.25 -> 0 | AC37: =AB37*11% -> 0 | AF37: =+AE37+AD37+Y37+U37+R37+Q37+AA37+S37+W37+AC37 -> 0 | AG37: =+O37-AF37 -> 0
A38: 39 | E38: 9 | H38: =+F38/30*G38 -> 0 | J38: =+I38*F38/30/E38 -> 0 | L38: =+K38*F38/30 -> 0 | O38: =+N38+M38+L38+J38+H38 -> 0 | Q38: =+F38/30/E38*P38 -> 0 | U38: =+F38/30*T38 -> 0 | W38: =+H38/30*V38 -> 0 | Y38: =+F38/30*X38*1 -> 0 | AA38: =+(F38/30*Z38)*0.25 -> 0 | AC38: =AB38*11% -> 0 | AF38: =+AE38+AD38+Y38+U38+R38+Q38+AA38+S38+W38+AC38 -> 0 | AG38: =+O38-AF38 -> 0
A39: 40 | E39: 9 | H39: =+F39/30*G39 -> 0 | J39: =+I39*F39/30/E39 -> 0 | L39: =+K39*F39/30 -> 0 | O39: =+N39+M39+L39+J39+H39 -> 0 | Q39: =+F39/30/E39*P39 -> 0 | U39: =+F39/30*T39 -> 0 | W39: =+H39/30*V39 -> 0 | Y39: =+F39/30*X39*1 -> 0 | AA39: =+(F39/30*Z39)*0.25 -> 0 | AC39: =AB39*11% -> 0 | AF39: =+AE39+AD39+Y39+U39+R39+Q39+AA39+S39+W39+AC39 -> 0 | AG39: =+O39-AF39 -> 0
... A113: 114 | E113: 9 | H113: =+F113/30*G113 -> 0 | J113: =+I113*F113/30/E113 -> 0 | L113: =+K113*F113/30 -> 0 | O113: =+N113+M113+L113+J113+H113 -> 0 | Q113: =+F113/30/E113*P113 -> 0 | U113: =+F113/30*T113 -> 0 | W113: =+H113/30*V113 -> 0 | Y113: =+F113/30*X113*1 -> 0 | AA113: =+(F113/30*Z113)*0.25 -> 0 | AC113: =AB113*11% -> 0 | AF113: =+AE113+AD113+Y113+U113+R113+Q113+AA113+S113+W113+AC113 -> 0 | AG113: =+O113-AF113 -> 0
E114: 9 | H114: =+F114/30*G114 -> 0 | J114: =+I114*F114/30/E114 -> 0 | L114: =+K114*F114/30 -> 0 | O114: =+N114+M114+L114+J114+H114 -> 0 | Q114: =+F114/30/E114*P114 -> 0 | U114: =+F114/30*T114 -> 0 | W114: =+H114/30*V114 -> 0 | Y114: =+F114/30*X114*1 -> 0 | AA114: =+(F114/30*Z114)*0.25 -> 0 | AC114: =AB114*11% -> 0 | AF114: =+AE114+AD114+Y114+U114+R114+Q114+AA114+S114+W114+AC114 -> 0 | AG114: =+O114-AF114 -> 0
...

Sheet فرع الاردنية
A1: مرتبات الاردنيه عن شهر 1-2025
A2: الكود | B2: الاسم | C2: الفرع | D2: الوظيفة | E2: ساعات العمل | F2: الراتب | G2: الاستحقاق | P2: الاستقطاع | AF2: اجمالى الاستقطاع | AG2: صافى الراتب | AH2: ملاحظات
G3: ايام العمل | H3: قيمة ايام العمل | I3: الاضافى بالساعات | J3: قيمة الاضافى | K3: بدل اجازات | L3: قيمة بدل الاجازات | M3: مكافأة | N3: اخرى | O3: اجمالى الاستحقاق | P3: ساعات التاخير | Q3: قيمة ساعات التأخير | R3: سلف | S3: سلفة مرحله | T3: جزاء ادارى | U3: قيمة الجزاء الادارى | V3: جزاء البصمه | W3: قيمة جزاء البصمه | X3: غياب بدون اذن | Y3: جزاء غياب بدون اذن | Z3: المرضى | AA3: قيمة المرضى | AB3: الراتب التاميني | AC3: تأمينات وضرائب | AD3: الانحرافات | AE3: عجز منتجات& عهدة

Sheet شرايط قبض الاردنية
A2: الكود | B2: الاسم | C2: الفرع | D2: الوظيفة | E2: ساعات العمل | F2: الراتب | P2: الاستقطاع | AF2: اجمالى الاستقطاع | AG2: صافى الراتب | AH2: ملاحظات
G3: ايام العمل | H3: قيمة ايام العمل | I3: الاضافى بالساعات | J3: قيمة الاضافى | K3: بدل اجازات | L3: قيمة بدل الاجازات | M3: مكافأة | N3: اخرى | O3: اجمالى الاستحقاق | P3: ساعات التاخير | Q3: قيمة ساعات التأخير | R3: سلف | S3: سلفة مرحله | T3: جزاء ادارى | U3: قيمة الجزاء الادارى | V3: جزاء البصمه | W3: قيمة جزاء البصمه | X3: غياب بدون اذن | Y3: جزاء غياب بدون اذن | Z3: المرضى | AA3: قيمة المرضى | AB3: الراتب التاميني | AC3: تأمينات وضرائب | AD3: الانحرافات | AE3: عجز منتجات& عهدة
A4: 1 | B4: ايه محمد عوضين سليمان | C4: فرع اسماعليه | D4: عضو فريق | E4: 9 | F4: 7000 | G4: 29 | H4: =+F4/30*G4 -> 6766.6667 | I4: 12 | J4: =+I4*F4/30/E4 -> 311.11111 | L4: =+K4*F4/30 -> 0 | O4: =+N4+M4+L4+J4+H4 -> 7077.7778 | Q4: =+F4/30/E4*P4 -> 0 | R4: 1600 | U4: =+F4/30*T4 -> 0 | W4: =+H4/30*V4 -> 0 | Y4: =+F4/30*X4*1 -> 0 | AA4: =+(F4/30*Z4)*0.25 -> 0 | AC4: =AB4*11% -> 0 | AF4: =+AE4+AD4+Y4+U4+R4+Q4+AA4+S4+W4+AC4 -> 1600 | AG4: =+O4-AF4 -> 5477.7778
A6: الكود | B6: الاسم | C6: الفرع | D6: الوظيفة | E6: ساعات العمل | F6: الراتب | G6: الاستحقاق | P6: الاستقطاع | AF6: اجمالى الاستقطاع | AG6: صافى الراتب | AH6: ملاحظات
G7: ايام العمل | H7: قيمة ايام العمل | I7: الاضافى بالساعات | J7: قيمة الاضافى | K7: بدل اجازات | L7: قيمة بدل الاجازات | M7: مكافأة | N7: اخرى | O7: اجمالى الاستحقاق | P7: ساعات التاخير | Q7: قيمة ساعات التأخير | R7: سلف | S7: سلفة مرحله | T7: جزاء ادارى | U7: قيمة الجزاء الادارى | V7: جزاء البصمه | W7: قيمة جزاء البصمه | X7: غياب بدون اذن | Y7: جزاء غياب بدون اذن | Z7: المرضى | AA7: قيمة المرضى | AB7: الراتب التاميني | AC7: تأمينات وضرائب | AD7: الانحرافات | AE7: عجز منتجات& عهدة
A8: 3 | B8: نورسين البغدادي ابراهيم سليم | C8: فرع اسماعليه | D8: عضو فريق | E8: 9 | F8: 7000 | G8: 29 | H8: =+F8/30*G8 -> 6766.6667 | I8: 12 | J8: =+I8*F8/30/E8 -> 311.11111 | L8: =+K8*F8/30 -> 0 | O8: =+N8+M8+L8+J8+H8 -> 7077.7778 | Q8: =+F8/30/E8*P8 -> 0 | R8: 500 | U8: =+F8/30*T8 -> 0 | W8: =+H8/30*V8 -> 0 | Y8: =+F8/30*X8*1 -> 0 | AA8: =+(F8/30*Z8)*0.25 -> 0 | AC8: =AB8*11% -> 0 | AF8: =+AE8+AD8+Y8+U8+R8+Q8+AA8+S8+W8+AC8 -> 500 | AG8: =+O8-AF8 -> 6577.7778
A10: الكود | B10: الاسم | C10: الفرع | D10: الوظيفة | E10: ساعات العمل | F10: الراتب | G10: الاستحقاق | P10: الاستقطاع | AF10: اجمالى الاستقطاع | AG10: صافى الراتب | AH10: ملاحظات
G11: ايام العمل | H11: قيمة ايام العمل | I11: الاضافى بالساعات | J11: قيمة الاضافى | K11: بدل اجازات | L11: قيمة بدل الاجازات | M11: مكافأة | N11: اخرى | O11: اجمالى الاستحقاق | P11: ساعات التاخير | Q11: قيمة ساعات التأخير | R11: سلف | S11: سلفة مرحله | T11: جزاء ادارى | U11: قيمة الجزاء الادارى | V11: جزاء البصمه | W11: قيمة جزاء البصمه | X11: غياب بدون اذن | Y11: جزاء غياب بدون اذن | Z11: المرضى | AA11: قيمة المرضى | AB11: الراتب التاميني | AC11: تأمينات وضرائب | AD11: الانحرافات | AE11: عجز منتجات& عهدة
A12: 4 | B12: مريم | C12: فرع اسماعليه | D12: كاشير | E12: 9 | F12: 6500 | G12: 30 | H12: =+F12/30*G12 -> 6500 | I12: 10 | J12: =+I12*F12/30/E12 -> 240.74074 | L12: =+K12*F12/30 -> 0 | O12: =+N12+M12+L12+J12+H12 -> 6740.7407 | P12: 6 | Q12: =+F12/30/E12*P12 -> 144.44444 | R12: 815 | U12: =+F12/30*T12 -> 0 | W12: =+H12/30*V12 -> 0 | Y12: =+F12/30*X12*1 -> 0 | AA12: =+(F12/30*Z12)*0.25 -> 0 | AC12: =AB12*11% -> 0 | AF12: =+AE12+AD12+Y12+U12+R12+Q12+AA12+S12+W12+AC12 -> 959.44444 | AG12: =+O12-AF12 -> 5781.2963
A14: الكود | B14: الاسم | C14: الفرع | D14: الوظيفة | E14: ساعات العمل | F14: الراتب | G14: الاستحقاق | P14: الاستقطاع | AF14: اجمالى الاستقطاع | AG14: صافى الراتب | AH14: ملاحظات
G15: ايام العمل | H15: قيمة ايام العمل | I15: الاضافى بالساعات | J15: قيمة الاضافى | K15: بدل اجازات | L15: قيمة بدل الاجازات | M15: مكافأة | N15: اخرى | O15: اجمالى الاستحقاق | P15: ساعات التاخير | Q15: قيمة ساعات التأخير | R15: سلف | S15: سلفة مرحله | T15: جزاء ادارى | U15: قيمة الجزاء الادارى | V15: جزاء البصمه | W15: قيمة جزاء البصمه | X15: غياب بدون اذن | Y15: جزاء غياب بدون اذن | Z15: المرضى | AA15: قيمة المرضى | AB15: الراتب التاميني | AC15: تأمينات وضرائب | AD15: الانحرافات | AE15: عجز منتجات& عهدة
A16: 5 | B16: سيد احمد حسن جاد الرب | C16: فرع اسماعليه | D16: عضو فريق | E16: 9 | F16: 6000 | G16: 29 | H16: =+F16/30*G16 -> 5800 | I16: 21 | J16: =+I16*F16/30/E16 -> 466.66667 | L16: =+K16*F16/30 -> 0 | O16: =+N16+M16+L16+J16+H16 -> 6266.6667 | P16: 4 | Q16: =+F16/30/E16*P16 -> 88.888889 | R16: 200 | U16: =+F16/30*T16 -> 0 | W16: =+H16/30*V16 -> 0 | Y16: =+F16/30*X16*1 -> 0 | AA16: =+(F16/30*Z16)*0.25 -> 0 | AC16: =AB16*11% -> 0 | AF16: =+AE16+AD16+Y16+U16+R16+Q16+AA16+S16+W16+AC16 -> 288.88889 | AG16: =+O16-AF16 -> 5977.7778
A18: الكود | B18: الاسم | C18: الفرع | D18: الوظيفة | E18: ساعات العمل | F18: الراتب | G18: الاستحقاق | P18: الاستقطاع | AF18: اجمالى الاستقطاع | AG18: صافى الراتب | AH18: ملاحظات
G19: ايام العمل | H19: قيمة ايام العمل | I19: الاضافى بالساعات | J19: قيمة الاضافى | K19: بدل اجازات | L19: قيمة بدل الاجازات | M19: مكافأة | N19: اخرى | O19: اجمالى الاستحقاق | P19: ساعات التاخير | Q19: قيمة ساعات التأخير | R19: سلف | S19: سلفة مرحله | T19: جزاء ادارى | U19: قيمة الجزاء الادارى | V19: جزاء البصمه | W19: قيمة جزاء البصمه | X19: غياب بدون اذن | Y19: جزاء غياب بدون اذن | Z19: المرضى | AA19: قيمة المرضى | AB19: الراتب التاميني | AC19: تأمينات وضرائب | AD19: الانحرافات | AE19: عجز منتجات& عهدة
A20: 6 | B20: احمد رمضان | C20: فرع اسماعليه | D20: عضو فريق | E20: 9 | F20: 6500 | G20: 29 | H20: =+F20/30*G20 -> 6283.3333 | I20: 2 | J20: =+I20*F20/30/E20 -> 48.148148 | L20: =+K20*F20/30 -> 0 | O20: =+N20+M20+L20+J20+H20 -> 6331.4815 | P20: 2 | Q20: =+F20/30/E20*P20 -> 48.148148 | R20: 3300 | T20: 2 | U20: =+F20/30*T20 -> 433.33333 | W20: =+H20/30*V20 -> 0 | Y20: =+F20/30*X20*1 -> 0 | AA20: =+(F20/30*Z20)*0.25 -> 0 | AC20: =AB20*11% -> 0 | AE20: 700 | AF20: =+AE20+AD20+Y20+U20+R20+Q20+AA20+S20+W20+AC20 -> 4481.4815 | AG20: =+O20-AF20 -> 1850 | AH20: 700ج تصليح الزجاج +خصم 2 يوم
A22: الكود | B22: الاسم | C22: الفرع | D22: الوظيفة | E22: ساعات العمل | F22: الراتب | G22: الاستحقاق | P22: الاستقطاع | AF22: اجمالى الاستقطاع | AG22: صافى الراتب | AH22: ملاحظات
G23: ايام العمل | H23: قيمة ايام العمل | I23: الاضافى بالساعات | J23: قيمة الاضافى | K23: بدل اجازات | L23: قيمة بدل الاجازات | M23: مكافأة | N23: اخرى | O23: اجمالى الاستحقاق | P23: ساعات التاخير | Q23: قيمة ساعات التأخير | R23: سلف | S23: سلفة مرحله | T23: جزاء ادارى | U23: قيمة الجزاء الادارى | V23: جزاء البصمه | W23: قيمة جزاء البصمه | X23: غياب بدون اذن | Y23: جزاء غياب بدون اذن | Z23: المرضى | AA23: قيمة المرضى | AB23: الراتب التاميني | AC23: تأمينات وضرائب | AD23: الانحرافات | AE23: عجز منتجات& عهدة
A24: 7 | B24: ابراهيم محمود | C24: فرع اسماعليه | D24: عضو فريق | E24: 9 | F24: 6000 | G24: 29 | H24: =+F24/30*G24 -> 5800 | I24: 22 | J24: =+I24*F24/30/E24 -> 488.88889 | L24: =+K24*F24/30 -> 0 | O24: =+N24+M24+L24+J24+H24 -> 6288.8889 | Q24: =+F24/30/E24*P24 -> 0 | U24: =+F24/30*T24 -> 0 | W24: =+H24/30*V24 -> 0 | Y24: =+F24/30*X24*1 -> 0 | AA24: =+(F24/30*Z24)*0.25 -> 0 | AC24: =AB24*11% -> 0 | AF24: =+AE24+AD24+Y24+U24+R24+Q24+AA24+S24+W24+AC24 -> 0 | AG24: =+O24-AF24 -> 6288.8889
A26: الكود | B26: الاسم | C26: الفرع | D26: الوظيفة | E26: ساعات العمل | F26: الراتب | G26: الاستحقاق | P26: الاستقطاع | AF26: اجمالى الاستقطاع | AG26: صافى الراتب | AH26: ملاحظات
G27: ايام العمل | H27: قيمة ايام العمل | I27: الاضافى بالساعات | J27: قيمة الاضافى | K27: بدل اجازات | L27: قيمة بدل الاجازات | M27: مكافأة | N27: اخرى | O27: اجمالى الاستحقاق | P27: ساعات التاخير | Q27: قيمة ساعات التأخير | R27: سلف | S27: سلفة مرحله | T27: جزاء ادارى | U27: قيمة الجزاء الادارى | V27: جزاء البصمه | W27: قيمة جزاء البصمه | X27: غياب بدون اذن | Y27: جزاء غياب بدون اذن | Z27: المرضى | AA27: قيمة المرضى | AB27: الراتب التاميني | AC27: تأمينات وضرائب | AD27: الانحرافات | AE27: عجز منتجات& عهدة
A28: 8 | B28: حسن محمد | C28: فرع اسماعليه | D28: ويتر | E28: 9 | F28: 6000 | G28: 26 | H28: =+F28/30*G28 -> 5200 | J28: =+I28*F28/30/E28 -> 0 | L28: =+K28*F28/30 -> 0 | O28: =+N28+M28+L28+J28+H28 -> 5200 | P28: 7 | Q28: =+F28/30/E28*P28 -> 155.55556 | R28: 1030 | U28: =+F28/30*T28 -> 0 | W28: =+H28/30*V28 -> 0 | X28: 3 | Y28: =+F28/30*X28*1 -> 600 | AA28: =+(F28/30*Z28)*0.25 -> 0 | AC28: =AB28*11% -> 0 | AF28: =+AE28+AD28+Y28+U28+R28+Q28+AA28+S28+W28+AC28 -> 1785.5556 | AG28: =+O28-AF28 -> 3414.4444 | AH28: عدم تنفيذ التعليمات الاداريه المكتوبه + غياب الجمعه
A30: الكود | B30: الاسم | C30: الفرع | D30: الوظيفة | E30: ساعات العمل | F30: الراتب | G30: الاستحقاق | P30: الاستقطاع | AF30: اجمالى الاستقطاع | AG30: صافى الراتب | AH30: ملاحظات
G31: ايام العمل | H31: قيمة ايام العمل | I31: الاضافى بالساعات | J31: قيمة الاضافى | K31: بدل اجازات | L31: قيمة بدل الاجازات | M31: مكافأة | N31: اخرى | O31: اجمالى الاستحقاق | P31: ساعات التاخير | Q31: قيمة ساعات التأخير | R31: سلف | S31: سلفة مرحله | T31: جزاء ادارى | U31: قيمة الجزاء الادارى | V31: جزاء البصمه | W31: قيمة جزاء البصمه | X31: غياب بدون اذن | Y31: جزاء غياب بدون اذن | Z31: المرضى | AA31: قيمة المرضى | AB31: الراتب التاميني | AC31: تأمينات وضرائب | AD31: الانحرافات | AE31: عجز منتجات& عهدة
A32: 9 | B32: نها | C32: فرع اسماعليه | D32: كاشير | E32: 9 | F32: 6000 | G32: 29 | H32: =+F32/30*G32 -> 5800 | I32: 4 | J32: =+I32*F32/30/E32 -> 88.888889 | L32: =+K32*F32/30 -> 0 | O32: =+N32+M32+L32+J32+H32 -> 5888.8889 | Q32: =+F32/30/E32*P32 -> 0 | R32: 2210 | U32: =+F32/30*T32 -> 0 | W32: =+H32/30*V32 -> 0 | Y32: =+F32/30*X32*1 -> 0 | AA32: =+(F32/30*Z32)*0.25 -> 0 | AC32: =AB32*11% -> 0 | AF32: =+AE32+AD32+Y32+U32+R32+Q32+AA32+S32+W32+AC32 -> 2210 | AG32: =+O32-AF32 -> 3678.8889
A34: الكود | B34: الاسم | C34: الفرع | D34: الوظيفة | E34: ساعات العمل | F34: الراتب | G34: الاستحقاق | P34: الاستقطاع | AF34: اجمالى الاستقطاع | AG34: صافى الراتب | AH34: ملاحظات
G35: ايام العمل | H35: قيمة ايام العمل | I35: الاضافى بالساعات | J35: قيمة الاضافى | K35: بدل اجازات | L35: قيمة بدل الاجازات | M35: مكافأة | N35: اخرى | O35: اجمالى الاستحقاق | P35: ساعات التاخير | Q35: قيمة ساعات التأخير | R35: سلف | S35: سلفة مرحله | T35: جزاء ادارى | U35: قيمة الجزاء الادارى | V35: جزاء البصمه | W35: قيمة جزاء البصمه | X35: غياب بدون اذن | Y35: جزاء غياب بدون اذن | Z35: المرضى | AA35: قيمة المرضى | AB35: الراتب التاميني | AC35: تأمينات وضرائب | AD35: الانحرافات | AE35: عجز منتجات& عهدة
A36: 14 | B36: احمد هادي ابرهيم متولي | C36: فرع اسماعليه | D36: مطبخ | E36: 9 | F36: 10000 | G36: 30 | H36: =+F36/30*G36 -> 10000 | J36: =+I36*F36/30/E36 -> 0 | L36: =+K36*F36/30 -> 0 | M36: 2000 | O36: =+N36+M36+L36+J36+H36 -> 12000 | P36: 3 | Q36: =+F36/30/E36*P36 -> 111.11111 | R36: 3440 | T36: 1 | U36: =+F36/30*T36 -> 333.33333 | W36: =+H36/30*V36 -> 0 | Y36: =+F36/30*X36*1 -> 0 | AA36: =+(F36/30*Z36)*0.25 -> 0 | AC36: =AB36*11% -> 0 | AE36: 175 | AF36: =+AE36+AD36+Y36+U36+R36+Q36+AA36+S36+W36+AC36 -> 4059.4444 | AG36: =+O36-AF36 -> 7940.5556 | AH36: خصم 4 قطع هالك
A38: الكود | B38: الاسم | C38: الفرع | D38: الوظيفة | E38: ساعات العمل | F38: الراتب | G38: الاستحقاق | P38: الاستقطاع | AF38: اجمالى الاستقطاع | AG38: صافى الراتب | AH38: ملاحظات
G39: ايام العمل | H39: قيمة ايام العمل | I39: الاضافى بالساعات | J39: قيمة الاضافى | K39: بدل اجازات | L39: قيمة بدل الاجازات | M39: مكافأة | N39: اخرى | O39: اجمالى الاستحقاق | P39: ساعات التاخير | Q39: قيمة ساعات التأخير | R39: سلف | S39: سلفة مرحله | T39: جزاء ادارى | U39: قيمة الجزاء الادارى | V39: جزاء البصمه | W39: قيمة جزاء البصمه | X39: غياب بدون اذن | Y39: جزاء غياب بدون اذن | Z39: المرضى | AA39: قيمة المرضى | AB39: الراتب التاميني | AC39: تأمينات وضرائب | AD39: الانحرافات | AE39: عجز منتجات& عهدة
A40: 15 | B40: مصطفي ابراهيم نبوي دراز | C40: فرع اسماعليه | D40: مدير فرع اسماعيليه | E40: 9 | F40: 10000 | G40: 30 | H40: =+F40/30*G40 -> 10000 | J40: =+I40*F40/30/E40 -> 0 | L40: =+K40*F40/30 -> 0 | M40: 2000 | O40: =+N40+M40+L40+J40+H40 -> 12000 | Q40: =+F40/30/E40*P40 -> 0 | R40: 1600 | U40: =+F40/30*T40 -> 0 | W40: =+H40/30*V40 -> 0 | Y40: =+F40/30*X40*1 -> 0 | AA40: =+(F40/30*Z40)*0.25 -> 0 | AC40: =AB40*11% -> 0 | AF40: =+AE40+AD40+Y40+U40+R40+Q40+AA40+S40+W40+AC40 -> 1600 | AG40: =+O40-AF40 -> 10400
A42: الكود | B42: الاسم | C42: الفرع | D42: الوظيفة | E42: ساعات العمل | F42: الراتب | G42: الاستحقاق | P42: الاستقطاع | AF42: اجمالى الاستقطاع | AG42: صافى الراتب | AH42: ملاحظات
G43: ايام العمل | H43: قيمة ايام العمل | I43: الاضافى بالساعات | J43: قيمة الاضافى | K43: بدل اجازات | L43: قيمة بدل الاجازات | M43: مكافأة | N43: اخرى | O43: اجمالى الاستحقاق | P43: ساعات التاخير | Q43: قيمة ساعات التأخير | R43: سلف | S43: سلفة مرحله | T43: جزاء ادارى | U43: قيمة الجزاء الادارى | V43: جزاء البصمه | W43: قيمة جزاء البصمه | X43: غياب بدون اذن | Y43: جزاء غياب بدون اذن | Z43: المرضى | AA43: قيمة المرضى | AB43: الراتب التاميني | AC43: تأمينات وضرائب | AD43: الانحرافات | AE43: عجز منتجات& عهدة
A44: 13 | B44: كريم خالد عبدالمريد دياب محمود | C44: فرع اسماعليه | D44: عضو فريق | E44: 9 | F44: 7500 | G44: 27 | H44: =+F44/30*G44 -> 6750 | J44: =+I44*F44/30/E44 -> 0 | L44: =+K44*F44/30 -> 0 | O44: =+N44+M44+L44+J44+H44 -> 6750 | Q44: =+F44/30/E44*P44 -> 0 | R44: 4725 | T44: 2 | U44: =+F44/30*T44 -> 500 | W44: =+H44/30*V44 -> 0 | Y44: =+F44/30*X44*1 -> 0 | AA44: =+(F44/30*Z44)*0.25 -> 0 | AC44: =AB44*11% -> 0 | AF44: =+AE44+AD44+Y44+U44+R44+Q44+AA44+S44+W44+AC44 -> 5225 | AG44: =+O44-AF44 -> 1525 | AH44: التطاول والمشاجرة مع مستر عصام + عم الالتزام بكتابه الحضور
A46: الكود | B46: الاسم | C46: الفرع | D46: الوظيفة | E46: ساعات العمل | F46: الراتب | G46: الاستحقاق | P46: الاستقطاع | AF46: اجمالى الاستقطاع | AG46: صافى الراتب | AH46: ملاحظات
G47: ايام العمل | H47: قيمة ايام العمل | I47: الاضافى بالساعات | J47: قيمة الاضافى | K47: بدل اجازات | L47: قيمة بدل الاجازات | M47: مكافأة | N47: اخرى | O47: اجمالى الاستحقاق | P47: ساعات التاخير | Q47: قيمة ساعات التأخير | R47: سلف | S47: سلفة مرحله | T47: جزاء ادارى | U47: قيمة الجزاء الادارى | V47: جزاء البصمه | W47: قيمة جزاء البصمه | X47: غياب بدون اذن | Y47: جزاء غياب بدون اذن | Z47: المرضى | AA47: قيمة المرضى | AB47: الراتب التاميني | AC47: تأمينات وضرائب | AD47: الانحرافات | AE47: عجز منتجات& عهدة
A48: 16 | B48: عبدالرحمن اوتاكا | C48: فرع اسماعليه | D48: كاشير | E48: 9 | F48: 6000 | G48: 21 | H48: =+F48/30*G48 -> 4200 | I48: 10 | J48: =+I48*F48/30/E48 -> 222.22222 | L48: =+K48*F48/30 -> 0 | O48: =+N48+M48+L48+J48+H48 -> 4422.2222 | P48: 2 | Q48: =+F48/30/E48*P48 -> 44.444444 | R48: 635 | U48: =+F48/30*T48 -> 0 | W48: =+H48/30*V48 -> 0 | Y48: =+F48/30*X48*1 -> 0 | AA48: =+(F48/30*Z48)*0.25 -> 0 | AC48: =AB48*11% -> 0 | AF48: =+AE48+AD48+Y48+U48+R48+Q48+AA48+S48+W48+AC48 -> 679.44444 | AG48: =+O48-AF48 -> 3742.7778
A50: الكود | B50: الاسم | C50: الفرع | D50: الوظيفة | E50: ساعات العمل | F50: الراتب | G50: الاستحقاق | P50: الاستقطاع | AF50: اجمالى الاستقطاع | AG50: صافى الراتب | AH50: ملاحظات
G51: ايام العمل | H51: قيمة ايام العمل | I51: الاضافى بالساعات | J51: قيمة الاضافى | K51: بدل اجازات | L51: قيمة بدل الاجازات | M51: مكافأة | N51: اخرى | O51: اجمالى الاستحقاق | P51: ساعات التاخير | Q51: قيمة ساعات التأخير | R51: سلف | S51: سلفة مرحله | T51: جزاء ادارى | U51: قيمة الجزاء الادارى | V51: جزاء البصمه | W51: قيمة جزاء البصمه | X51: غياب بدون اذن | Y51: جزاء غياب بدون اذن | Z51: المرضى | AA51: قيمة المرضى | AB51: الراتب التاميني | AC51: تأمينات وضرائب | AD51: الانحرافات | AE51: عجز منتجات& عهدة
A52: 17 | B52: شريف عاطف | C52: فرع اسماعليه | D52: مطبخ | E52: 9 | F52: 10000 | G52: 30 | H52: =+F52/30*G52 -> 10000 | I52: 50 | J52: =+I52*F52/30/E52 -> 1851.8519 | L52: =+K52*F52/30 -> 0 | O52: =+N52+M52+L52+J52+H52 -> 11851.852 | Q52: =+F52/30/E52*P52 -> 0 | R52: 3000 | U52: =+F52/30*T52 -> 0 | W52: =+H52/30*V52 -> 0 | Y52: =+F52/30*X52*1 -> 0 | AA52: =+(F52/30*Z52)*0.25 -> 0 | AC52: =AB52*11% -> 0 | AF52: =+AE52+AD52+Y52+U52+R52+Q52+AA52+S52+W52+AC52 -> 3000 | AG52: =+O52-AF52 -> 8851.8519
A54: الكود | B54: الاسم | C54: الفرع | D54: الوظيفة | E54: ساعات العمل | F54: الراتب | G54: الاستحقاق | P54: الاستقطاع | AF54: اجمالى الاستقطاع | AG54: صافى الراتب | AH54: ملاحظات
...

Sheet فرع الرواد
A1: مرتبات الاردنيه عن شهر 1-2025
A2: الكود | B2: الاسم | C2: الفرع | D2: الوظيفة | E2: ساعات العمل | F2: الراتب | G2: الاستحقاق | P2: الاستقطاع | AF2: اجمالى الاستقطاع | AG2: صافى الراتب | AH2: ملاحظات
G3: ايام العمل | H3: قيمة ايام العمل | I3: الاضافى بالساعات | J3: قيمة الاضافى | K3: بدل اجازات | L3: قيمة بدل الاجازات | M3: مكافأة | N3: اخرى | O3: اجمالى الاستحقاق | P3: ساعات التاخير | Q3: قيمة ساعات التأخير | R3: سلف | S3: سلفة مرحله | T3: جزاء ادارى | U3: قيمة الجزاء الادارى | V3: جزاء البصمه | W3: قيمة جزاء البصمه | X3: غياب بدون اذن | Y3: جزاء غياب بدون اذن | Z3: المرضى | AA3: قيمة المرضى | AB3: الراتب التاميني | AC3: تأمينات وضرائب | AD3: الانحرافات | AE3: عجز منتجات& عهدة

Sheet شرايط قبض الرواد
A2: الكود | B2: الاسم | C2: الفرع | D2: الوظيفة | E2: ساعات العمل | F2: الراتب | P2: الاستقطاع | AF2: اجمالى الاستقطاع | AG2: صافى الراتب | AH2: ملاحظات
G3: ايام العمل | H3: قيمة ايام العمل | I3: الاضافى بالساعات | J3: قيمة الاضافى | K3: بدل اجازات | L3: قيمة بدل الاجازات | M3: مكافأة | N3: اخرى | O3: اجمالى الاستحقاق | P3: ساعات التاخير | Q3: قيمة ساعات التأخير | R3: سلف | S3: سلفة مرحله | T3: جزاء ادارى | U3: قيمة الجزاء الادارى | V3: جزاء البصمه | W3: قيمة جزاء البصمه | X3: غياب بدون اذن | Y3: جزاء غياب بدون اذن | Z3: المرضى | AA3: قيمة المرضى | AB3: الراتب التاميني | AC3: تأمينات وضرائب | AD3: الانحرافات | AE3: عجز منتجات& عهدة
A4: =+'فرع الرواد'!A4 -> 0 | B4: =+'فرع الرواد'!B4 -> 0 | C4: =+'فرع الرواد'!C4 -> 0 | D4: =+'فرع الرواد'!D4 -> 0 | E4: =+'فرع الرواد'!E4 -> 0 | F4: ='فرع الرواد'!F4 -> 0 | G4: ='فرع الرواد'!G4 -> 0 | H4: ='فرع الرواد'!H4 -> 0 | I4: ='فرع الرواد'!I4 -> 0 | J4: ='فرع الرواد'!J4 -> 0 | K4: ='فرع الرواد'!K4 -> 0 | L4: ='فرع الرواد'!L4 -> 0 | M4: ='فرع الرواد'!M4 -> 0 | ... AH4: ='فرع الرواد'!AH4 -> 0
A6: الكود | B6: الاسم | C6: الفرع | D6: الوظيفة | E6: ساعات العمل | F6: الراتب | G6: الاستحقاق | P6: الاستقطاع | AF6: اجمالى الاستقطاع | AG6: صافى الراتب | AH6: ملاحظات
G7: ايام العمل | H7: قيمة ايام العمل | I7: الاضافى بالساعات | J7: قيمة الاضافى | K7: بدل اجازات | L7: قيمة بدل الاجازات | M7: مكافأة | N7: اخرى | O7: اجمالى الاستحقاق | P7: ساعات التاخير | Q7: قيمة ساعات التأخير | R7: سلف | S7: سلفة مرحله | T7: جزاء ادارى | U7: قيمة الجزاء الادارى | V7: جزاء البصمه | W7: قيمة جزاء البصمه | X7: غياب بدون اذن | Y7: جزاء غياب بدون اذن | Z7: المرضى | AA7: قيمة المرضى | AB7: الراتب التاميني | AC7: تأمينات وضرائب | AD7: الانحرافات | AE7: عجز منتجات& عهدة
A8: =+'فرع الرواد'!A5 -> 0 | B8: =+'فرع الرواد'!B5 -> 0 | C8: =+'فرع الرواد'!C5 -> 0 | D8: =+'فرع الرواد'!D5 -> 0 | E8: =+'فرع الرواد'!E5 -> 0 | F8: =+'فرع الرواد'!F5 -> 0 | G8: =+'فرع الرواد'!G5 -> 0 | H8: =+'فرع الرواد'!H5 -> 0 | ... AH8: =+'فرع الرواد'!AH5 -> 0
A10: الكود | B10: الاسم | C10: الفرع | D10: الوظيفة | E10: ساعات العمل | F10: الراتب | G10: الاستحقاق | P10: الاستقطاع | AF10: اجمالى الاستقطاع | AG10: صافى الراتب | AH10: ملاحظات
G11: ايام العمل | H11: قيمة ايام العمل | I11: الاضافى بالساعات | J11: قيمة الاضافى | K11: بدل اجازات | L11: قيمة بدل الاجازات | M11: مكافأة | N11: اخرى | O11: اجمالى الاستحقاق | P11: ساعات التاخير | Q11: قيمة ساعات التأخير | R11: سلف | S11: سلفة مرحله | T11: جزاء ادارى | U11: قيمة الجزاء الادارى | V11: جزاء البصمه | W11: قيمة جزاء البصمه | X11: غياب بدون اذن | Y11: جزاء غياب بدون اذن | Z11: المرضى | AA11: قيمة المرضى | AB11: الراتب التاميني | AC11: تأمينات وضرائب | AD11: الانحرافات | AE11: عجز منتجات& عهدة
A12: =+'فرع الرواد'!A6 -> 0 | B12: =+'فرع الرواد'!B6 -> 0 | C12: =+'فرع الرواد'!C6 -> 0 | D12: =+'فرع الرواد'!D6 -> 0 | E12: =+'فرع الرواد'!E6 -> 0 | F12: =+'فرع الرواد'!F6 -> 0 | G12: =+'فرع الرواد'!G6 -> 0 | H12: =+'فرع الرواد'!H6 -> 0 | ... AH12: =+'فرع الرواد'!AH6 -> 0
A14: الكود | B14: الاسم | C14: الفرع | D14: الوظيفة | E14: ساعات العمل | F14: الراتب | G14: الاستحقاق | P14: الاستقطاع | AF14: اجمالى الاستقطاع | AG14: صافى الراتب | AH14: ملاحظات
G15: ايام العمل | H15: قيمة ايام العمل | I15: الاضافى بالساعات | J15: قيمة الاضافى | K15: بدل اجازات | L15: قيمة بدل الاجازات | M15: مكافأة | N15: اخرى | O15: اجمالى الاستحقاق | P15: ساعات التاخير | Q15: قيمة ساعات التأخير | R15: سلف | S15: سلفة مرحله | T15: جزاء ادارى | U15: قيمة الجزاء الادارى | V15: جزاء البصمه | W15: قيمة جزاء البصمه | X15: غياب بدون اذن | Y15: جزاء غياب بدون اذن | Z15: المرضى | AA15: قيمة المرضى | AB15: الراتب التاميني | AC15: تأمينات وضرائب | AD15: الانحرافات | AE15: عجز منتجات& عهدة
A16: =+'فرع الرواد'!A7 -> 0 | B16: =+'فرع الرواد'!B7 -> 0 | C16: =+'فرع الرواد'!C7 -> 0 | D16: =+'فرع الرواد'!D7 -> 0 | E16: =+'فرع الرواد'!E7 -> 0 | F16: =+'فرع الرواد'!F7 -> 0 | G16: =+'فرع الرواد'!G7 -> 0 | H16: =+'فرع الرواد'!H7 -> 0 | ... AH16: =+'فرع الرواد'!AH7 -> 0
A18: الكود | B18: الاسم | C18: الفرع | D18: الوظيفة | E18: ساعات العمل | F18: الراتب | G18: الاستحقاق | P18: الاستقطاع | AF18: اجمالى الاستقطاع | AG18: صافى الراتب | AH18: ملاحظات
G19: ايام العمل | H19: قيمة ايام العمل | I19: الاضافى بالساعات | J19: قيمة الاضافى | K19: بدل اجازات | L19: قيمة بدل الاجازات | M19: مكافأة | N19: اخرى | O19: اجمالى الاستحقاق | P19: ساعات التاخير | Q19: قيمة ساعات التأخير | R19: سلف | S19: سلفة مرحله | T19: جزاء ادارى | U19: قيمة الجزاء الادارى | V19: جزاء البصمه | W19: قيمة جزاء البصمه | X19: غياب بدون اذن | Y19: جزاء غياب بدون اذن | Z19: المرضى | AA19: قيمة المرضى | AB19: الراتب التاميني | AC19: تأمينات وضرائب | AD19: الانحرافات | AE19: عجز منتجات& عهدة
A20: =+'فرع الرواد'!A8 -> 0 | B20: =+'فرع الرواد'!B8 -> 0 | C20: =+'فرع الرواد'!C8 -> 0 | D20: =+'فرع الرواد'!D8 -> 0 | E20: =+'فرع الرواد'!E8 -> 0 | F20: =+'فرع الرواد'!F8 -> 0 | G20: =+'فرع الرواد'!G8 -> 0 | H20: =+'فرع الرواد'!H8 -> 0 | ... AH20: =+'فرع الرواد'!AH8 -> 0
A22: الكود | B22: الاسم | C22: الفرع | D22: الوظيفة | E22: ساعات العمل | F22: الراتب | G22: الاستحقاق | P22: الاستقطاع | AF22: اجمالى الاستقطاع | AG22: صافى الراتب | AH22: ملاحظات
G23: ايام العمل | H23: قيمة ايام العمل | I23: الاضافى بالساعات | J23: قيمة الاضافى | K23: بدل اجازات | L23: قيمة بدل الاجازات | M23: مكافأة | N23: اخرى | O23: اجمالى الاستحقاق | P23: ساعات التاخير | Q23: قيمة ساعات التأخير | R23: سلف | S23: سلفة مرحله | T23: جزاء ادارى | U23: قيمة الجزاء الادارى | V23: جزاء البصمه | W23: قيمة جزاء البصمه | X23: غياب بدون اذن | Y23: جزاء غياب بدون اذن | Z23: المرضى | AA23: قيمة المرضى | AB23: الراتب التاميني | AC23: تأمينات وضرائب | AD23: الانحرافات | AE23: عجز منتجات& عهدة
A24: =+'فرع الرواد'!A9 -> 0 | B24: =+'فرع الرواد'!B9 -> 0 | C24: =+'فرع الرواد'!C9 -> 0 | D24: =+'فرع الرواد'!D9 -> 0 | E24: =+'فرع الرواد'!E9 -> 0 | F24: =+'فرع الرواد'!F9 -> 0 | G24: =+'فرع الرواد'!G9 -> 0 | H24: =+'فرع الرواد'!H9 -> 0 | ... AH24: =+'فرع الرواد'!AH9 -> 0
A26: الكود | B26: الاسم | C26: الفرع | D26: الوظيفة | E26: ساعات العمل | F26: الراتب | G26: الاستحقاق | P26: الاستقطاع | AF26: اجمالى الاستقطاع | AG26: صافى الراتب | AH26: ملاحظات
G27: ايام العمل | H27: قيمة ايام العمل | I27: الاضافى بالساعات | J27: قيمة الاضافى | K27: بدل اجازات | L27: قيمة بدل الاجازات | M27: مكافأة | N27: اخرى | O27: اجمالى الاستحقاق | P27: ساعات التاخير | Q27: قيمة ساعات التأخير | R27: سلف | S27: سلفة مرحله | T27: جزاء ادارى | U27: قيمة الجزاء الادارى | V27: جزاء البصمه | W27: قيمة جزاء البصمه | X27: غياب بدون اذن | Y27: جزاء غياب بدون اذن | Z27: المرضى | AA27: قيمة المرضى | AB27: الراتب التاميني | AC27: تأمينات وضرائب | AD27: الانحرافات | AE27: عجز منتجات& عهدة
A28: =+'فرع الرواد'!A10 -> 0 | B28: =+'فرع الرواد'!B10 -> 0 | C28: =+'فرع الرواد'!C10 -> 0 | D28: =+'فرع الرواد'!D10 -> 0 | E28: =+'فرع الرواد'!E10 -> 0 | F28: =+'فرع الرواد'!F10 -> 0 | G28: =+'فرع الرواد'!G10 -> 0 | H28: =+'فرع الرواد'!H10 -> 0 | ... AH28: =+'فرع الرواد'!AH10 -> 0
A30: الكود | B30: الاسم | C30: الفرع | D30: الوظيفة | E30: ساعات العمل | F30: الراتب | G30: الاستحقاق | P30: الاستقطاع | AF30: اجمالى الاستقطاع | AG30: صافى الراتب | AH30: ملاحظات
G31: ايام العمل | H31: قيمة ايام العمل | I31: الاضافى بالساعات | J31: قيمة الاضافى | K31: بدل اجازات | L31: قيمة بدل الاجازات | M31: مكافأة | N31: اخرى | O31: اجمالى الاستحقاق | P31: ساعات التاخير | Q31: قيمة ساعات التأخير | R31: سلف | S31: سلفة مرحله | T31: جزاء ادارى | U31: قيمة الجزاء الادارى | V31: جزاء البصمه | W31: قيمة جزاء البصمه | X31: غياب بدون اذن | Y31: جزاء غياب بدون اذن | Z31: المرضى | AA31: قيمة المرضى | AB31: الراتب التاميني | AC31: تأمينات وضرائب | AD31: الانحرافات | AE31: عجز منتجات& عهدة
A32: =+'فرع الرواد'!A11 -> 0 | B32: =+'فرع الرواد'!B11 -> 0 | C32: =+'فرع الرواد'!C11 -> 0 | D32: =+'فرع الرواد'!D11 -> 0 | E32: =+'فرع الرواد'!E11 -> 0 | F32: =+'فرع الرواد'!F11 -> 0 | G32: =+'فرع الرواد'!G11 -> 0 | H32: =+'فرع الرواد'!H11 -> 0 | ... AH32: =+'فرع الرواد'!AH11 -> 0
A34: الكود | B34: الاسم | C34: الفرع | D34: الوظيفة | E34: ساعات العمل | F34: الراتب | G34: الاستحقاق | P34: الاستقطاع | AF34: اجمالى الاستقطاع | AG34: صافى الراتب | AH34: ملاحظات
G35: ايام العمل | H35: قيمة ايام العمل | I35: الاضافى بالساعات | J35: قيمة الاضافى | K35: بدل اجازات | L35: قيمة بدل الاجازات | M35: مكافأة | N35: اخرى | O35: اجمالى الاستحقاق | P35: ساعات التاخير | Q35: قيمة ساعات التأخير | R35: سلف | S35: سلفة مرحله | T35: جزاء ادارى | U35: قيمة الجزاء الادارى | V35: جزاء البصمه | W35: قيمة جزاء البصمه | X35: غياب بدون اذن | Y35: جزاء غياب بدون اذن | Z35: المرضى | AA35: قيمة المرضى | AB35: الراتب التاميني | AC35: تأمينات وضرائب | AD35: الانحرافات | AE35: عجز منتجات& عهدة
A36: =+'فرع الرواد'!A12 -> 0 | B36: =+'فرع الرواد'!B12 -> 0 | C36: =+'فرع الرواد'!C12 -> 0 | D36: =+'فرع الرواد'!D12 -> 0 | E36: =+'فرع الرواد'!E12 -> 0 | F36: =+'فرع الرواد'!F12 -> 0 | G36: =+'فرع الرواد'!G12 -> 0 | H36: =+'فرع الرواد'!H12 -> 0 | ... AH36: =+'فرع الرواد'!AH12 -> 0
A38: الكود | B38: الاسم | C38: الفرع | D38: الوظيفة | E38: ساعات العمل | F38: الراتب | G38: الاستحقاق | P38: الاستقطاع | AF38: اجمالى الاستقطاع | AG38: صافى الراتب | AH38: ملاحظات
G39: ايام العمل | H39: قيمة ايام العمل | I39: الاضافى بالساعات | J39: قيمة الاضافى | K39: بدل اجازات | L39: قيمة بدل الاجازات | M39: مكافأة | N39: اخرى | O39: اجمالى الاستحقاق | P39: ساعات التاخير | Q39: قيمة ساعات التأخير | R39: سلف | S39: سلفة مرحله | T39: جزاء ادارى | U39: قيمة الجزاء الادارى | V39: جزاء البصمه | W39: قيمة جزاء البصمه | X39: غياب بدون اذن | Y39: جزاء غياب بدون اذن | Z39: المرضى | AA39: قيمة المرضى | AB39: الراتب التاميني | AC39: تأمينات وضرائب | AD39: الانحرافات | AE39: عجز منتجات& عهدة
A40: =+'فرع الرواد'!A13 -> 0 | B40: =+'فرع الرواد'!B13 -> 0 | C40: =+'فرع الرواد'!C13 -> 0 | D40: =+'فرع الرواد'!D13 -> 0 | E40: =+'فرع الرواد'!E13 -> 0 | F40: =+'فرع الرواد'!F13 -> 0 | G40: =+'فرع الرواد'!G13 -> 0 | H40: =+'فرع الرواد'!H13 -> 0 | ... AH40: =+'فرع الرواد'!AH13 -> 0
A42: الكود | B42: الاسم | C42: الفرع | D42: الوظيفة | E42: ساعات العمل | F42: الراتب | G42: الاستحقاق | P42: الاستقطاع | AF42: اجمالى الاستقطاع | AG42: صافى الراتب | AH42: ملاحظات
G43: ايام العمل | H43: قيمة ايام العمل | I43: الاضافى بالساعات | J43: قيمة الاضافى | K43: بدل اجازات | L43: قيمة بدل الاجازات | M43: مكافأة | N43: اخرى | O43: اجمالى الاستحقاق | P43: ساعات التاخير | Q43: قيمة ساعات التأخير | R43: سلف | S43: سلفة مرحله | T43: جزاء ادارى | U43: قيمة الجزاء الادارى | V43: جزاء البصمه | W43: قيمة جزاء البصمه | X43: غياب بدون اذن | Y43: جزاء غياب بدون اذن | Z43: المرضى | AA43: قيمة المرضى | AB43: الراتب التاميني | AC43: تأمينات وضرائب | AD43: الانحرافات | AE43: عجز منتجات& عهدة
A44: =+'فرع الرواد'!A14 -> 0 | B44: =+'فرع الرواد'!B14 -> 0 | C44: =+'فرع الرواد'!C14 -> 0 | D44: =+'فرع الرواد'!D14 -> 0 | E44: =+'فرع الرواد'!E14 -> 0 | F44: =+'فرع الرواد'!F14 -> 0 | G44: =+'فرع الرواد'!G14 -> 0 | H44: =+'فرع الرواد'!H14 -> 0 | ... AH44: =+'فرع الرواد'!AH14 -> 0
A46: الكود | B46: الاسم | C46: الفرع | D46: الوظيفة | E46: ساعات العمل | F46: الراتب | G46: الاستحقاق | P46: الاستقطاع | AF46: اجمالى الاستقطاع | AG46: صافى الراتب | AH46: ملاحظات
G47: ايام العمل | H47: قيمة ايام العمل | I47: الاضافى بالساعات | J47: قيمة الاضافى | K47: بدل اجازات | L47: قيمة بدل الاجازات | M47: مكافأة | N47: اخرى | O47: اجمالى الاستحقاق | P47: ساعات التاخير | Q47: قيمة ساعات التأخير | R47: سلف | S47: سلفة مرحله | T47: جزاء ادارى | U47: قيمة الجزاء الادارى | V47: جزاء البصمه | W47: قيمة جزاء البصمه | X47: غياب بدون اذن | Y47: جزاء غياب بدون اذن | Z47: المرضى | AA47: قيمة المرضى | AB47: الراتب التاميني | AC47: تأمينات وضرائب | AD47: الانحرافات | AE47: عجز منتجات& عهدة
A48: =+'فرع الرواد'!A15 -> 0 | B48: =+'فرع الرواد'!B15 -> 0 | C48: =+'فرع الرواد'!C15 -> 0 | D48: =+'فرع الرواد'!D15 -> 0 | E48: =+'فرع الرواد'!E15 -> 0 | F48: =+'فرع الرواد'!F15 -> 0 | G48: =+'فرع الرواد'!G15 -> 0 | H48: =+'فرع الرواد'!H15 -> 0 | ... AH48: =+'فرع الرواد'!AH15 -> 0
A50: الكود | B50: الاسم | C50: الفرع | D50: الوظيفة | E50: ساعات العمل | F50: الراتب | G50: الاستحقاق | P50: الاستقطاع | AF50: اجمالى الاستقطاع | AG50: صافى الراتب | AH50: ملاحظات
G51: ايام العمل | H51: قيمة ايام العمل | I51: الاضافى بالساعات | J51: قيمة الاضافى | K51: بدل اجازات | L51: قيمة بدل الاجازات | M51: مكافأة | N51: اخرى | O51: اجمالى الاستحقاق | P51: ساعات التاخير | Q51: قيمة ساعات التأخير | R51: سلف | S51: سلفة مرحله | T51: جزاء ادارى | U51: قيمة الجزاء الادارى | V51: جزاء البصمه | W51: قيمة جزاء البصمه | X51: غياب بدون اذن | Y51: جزاء غياب بدون اذن | Z51: المرضى | AA51: قيمة المرضى | AB51: الراتب التاميني | AC51: تأمينات وضرائب | AD51: الانحرافات | AE51: عجز منتجات& عهدة
A52: =+'فرع الرواد'!A16 -> 0 | B52: =+'فرع الرواد'!B16 -> 0 | C52: =+'فرع الرواد'!C16 -> 0 | D52: =+'فرع الرواد'!D16 -> 0 | E52: =+'فرع الرواد'!E16 -> 0 | F52: =+'فرع الرواد'!F16 -> 0 | G52: =+'فرع الرواد'!G16 -> 0 | H52: =+'فرع الرواد'!H16 -> 0 | ... AH52: =+'فرع الرواد'!AH16 -> 0
A54: الكود | B54: الاسم | C54: الفرع | D54: الوظيفة | E54: ساعات العمل | F54: الراتب | G54: الاستحقاق | P54: الاستقطاع | AF54: اجمالى الاستقطاع | AG54: صافى الراتب | AH54: ملاحظات
...

Sheet فرع الزقازيق
A1: مرتبات الاردنيه عن شهر 1-2025
A2: الكود | B2: الاسم | C2: الفرع | D2: الوظيفة | E2: ساعات العمل | F2: الراتب | G2: الاستحقاق | P2: الاستقطاع | AF2: اجمالى الاستقطاع | AG2: صافى الراتب | AH2: ملاحظات
G3: ايام العمل | H3: قيمة ايام العمل | I3: الاضافى بالساعات | J3: قيمة الاضافى | K3: بدل اجازات | L3: قيمة بدل الاجازات | M3: مكافأة | N3: اخرى | O3: اجمالى الاستحقاق | P3: ساعات التاخير | Q3: قيمة ساعات التأخير | R3: سلف | S3: سلفة مرحله | T3: جزاء ادارى | U3: قيمة الجزاء الادارى | V3: جزاء البصمه | W3: قيمة جزاء البصمه | X3: غياب بدون اذن | Y3: جزاء غياب بدون اذن | Z3: المرضى | AA3: قيمة المرضى | AB3: الراتب التاميني | AC3: تأمينات وضرائب | AD3: الانحرافات | AE3: عجز منتجات& عهدة

Sheet شرايط قبض الزقازيق
A2: الكود | B2: الاسم | C2: الفرع | D2: الوظيفة | E2: ساعات العمل | F2: الراتب | P2: الاستقطاع | AF2: اجمالى الاستقطاع | AG2: صافى الراتب | AH2: ملاحظات
G3: ايام العمل | H3: قيمة ايام العمل | I3: الاضافى بالساعات | J3: قيمة الاضافى | K3: بدل اجازات | L3: قيمة بدل الاجازات | M3: مكافأة | N3: اخرى | O3: اجمالى الاستحقاق | P3: ساعات التاخير | Q3: قيمة ساعات التأخير | R3: سلف | S3: سلفة مرحله | T3: جزاء ادارى | U3: قيمة الجزاء الادارى | V3: جزاء البصمه | W3: قيمة جزاء البصمه | X3: غياب بدون اذن | Y3: جزاء غياب بدون اذن | Z3: المرضى | AA3: قيمة المرضى | AB3: الراتب التاميني | AC3: تأمينات وضرائب | AD3: الانحرافات | AE3: عجز منتجات& عهدة
A4: =+'فرع الزقازيق'!A4 -> 0 | B4: =+'فرع الزقازيق'!B4 -> 0 | C4: =+'فرع الزقازيق'!C4 -> 0 | D4: =+'فرع الزقازيق'!D4 -> 0 | E4: =+'فرع الزقازيق'!E4 -> 0 | F4: ='فرع الزقازيق'!F4 -> 0 | G4: ='فرع الزقازيق'!G4 -> 0 | H4: ='فرع الزقازيق'!H4 -> 0 | I4: ='فرع الزقازيق'!I4 -> 0 | J4: ='فرع الزقازيق'!J4 -> 0 | K4: ='فرع الزقازيق'!K4 -> 0 | L4: ='فرع الزقازيق'!L4 -> 0 | M4: ='فرع الزقازيق'!M4 -> 0 | ... AH4: ='فرع الزقازيق'!AH4 -> 0
A6: الكود | B6: الاسم | C6: الفرع | D6: الوظيفة | E6: ساعات العمل | F6: الراتب | G6: الاستحقاق | P6: الاستقطاع | AF6: اجمالى الاستقطاع | AG6: صافى الراتب | AH6: ملاحظات
G7: ايام العمل | H7: قيمة ايام العمل | I7: الاضافى بالساعات | J7: قيمة الاضافى | K7: بدل اجازات | L7: قيمة بدل الاجازات | M7: مكافأة | N7: اخرى | O7: اجمالى الاستحقاق | P7: ساعات التاخير | Q7: قيمة ساعات التأخير | R7: سلف | S7: سلفة مرحله | T7: جزاء ادارى | U7: قيمة الجزاء الادارى | V7: جزاء البصمه | W7: قيمة جزاء البصمه | X7: غياب بدون اذن | Y7: جزاء غياب بدون اذن | Z7: المرضى | AA7: قيمة المرضى | AB7: الراتب التاميني | AC7: تأمينات وضرائب | AD7: الانحرافات | AE7: عجز منتجات& عهدة
A8: =+'فرع الزقازيق'!A5 -> 0 | B8: =+'فرع الزقازيق'!B5 -> 0 | C8: =+'فرع الزقازيق'!C5 -> 0 | D8: =+'فرع الزقازيق'!D5 -> 0 | E8: =+'فرع الزقازيق'!E5 -> 0 | F8: =+'فرع الزقازيق'!F5 -> 0 | G8: =+'فرع الزقازيق'!G5 -> 0 | H8: =+'فرع الزقازيق'!H5 -> 0 | ... AH8: =+'فرع الزقازيق'!AH5 -> 0
A10: الكود | B10: الاسم | C10: الفرع | D10: الوظيفة | E10: ساعات العمل | F10: الراتب | G10: الاستحقاق | P10: الاستقطاع | AF10: اجمالى الاستقطاع | AG10: صافى الراتب | AH10: ملاحظات
G11: ايام العمل | H11: قيمة ايام العمل | I11: الاضافى بالساعات | J11: قيمة الاضافى | K11: بدل اجازات | L11: قيمة بدل الاجازات | M11: مكافأة | N11: اخرى | O11: اجمالى الاستحقاق | P11: ساعات التاخير | Q11: قيمة ساعات التأخير | R11: سلف | S11: سلفة مرحله | T11: جزاء ادارى | U11: قيمة الجزاء الادارى | V11: جزاء البصمه | W11: قيمة جزاء البصمه | X11: غياب بدون اذن | Y11: جزاء غياب بدون اذن | Z11: المرضى | AA11: قيمة المرضى | AB11: الراتب التاميني | AC11: تأمينات وضرائب | AD11: الانحرافات | AE11: عجز منتجات& عهدة
A12: =+'فرع الزقازيق'!A6 -> 0 | B12: =+'فرع الزقازيق'!B6 -> 0 | C12: =+'فرع الزقازيق'!C6 -> 0 | D12: =+'فرع الزقازيق'!D6 -> 0 | E12: =+'فرع الزقازيق'!E6 -> 0 | F12: =+'فرع الزقازيق'!F6 -> 0 | G12: =+'فرع الزقازيق'!G6 -> 0 | H12: =+'فرع الزقازيق'!H6 -> 0 | ... AH12: =+'فرع الزقازيق'!AH6 -> 0
A14: الكود | B14: الاسم | C14: الفرع | D14: الوظيفة | E14: ساعات العمل | F14: الراتب | G14: الاستحقاق | P14: الاستقطاع | AF14: اجمالى الاستقطاع | AG14: صافى الراتب | AH14: ملاحظات
G15: ايام العمل | H15: قيمة ايام العمل | I15: الاضافى بالساعات | J15: قيمة الاضافى | K15: بدل اجازات | L15: قيمة بدل الاجازات | M15: مكافأة | N15: اخرى | O15: اجمالى الاستحقاق | P15: ساعات التاخير | Q15: قيمة ساعات التأخير | R15: سلف | S15: سلفة مرحله | T15: جزاء ادارى | U15: قيمة الجزاء الادارى | V15: جزاء البصمه | W15: قيمة جزاء البصمه | X15: غياب بدون اذن | Y15: جزاء غياب بدون اذن | Z15: المرضى | AA15: قيمة المرضى | AB15: الراتب التاميني | AC15: تأمينات وضرائب | AD15: الانحرافات | AE15: عجز منتجات& عهدة
A16: =+'فرع الزقازيق'!A7 -> 0 | B16: =+'فرع الزقازيق'!B7 -> 0 | C16: =+'فرع الزقازيق'!C7 -> 0 | D16: =+'فرع الزقازيق'!D7 -> 0 | E16: =+'فرع الزقازيق'!E7 -> 0 | F16: =+'فرع الزقازيق'!F7 -> 0 | G16: =+'فرع الزقازيق'!G7 -> 0 | H16: =+'فرع الزقازيق'!H7 -> 0 | ... AH16: =+'فرع الزقازيق'!AH7 -> 0
A18: الكود | B18: الاسم | C18: الفرع | D18: الوظيفة | E18: ساعات العمل | F18: الراتب | G18: الاستحقاق | P18: الاستقطاع | AF18: اجمالى الاستقطاع | AG18: صافى الراتب | AH18: ملاحظات
G19: ايام العمل | H19: قيمة ايام العمل | I19: الاضافى بالساعات | J19: قيمة الاضافى | K19: بدل اجازات | L19: قيمة بدل الاجازات | M19: مكافأة | N19: اخرى | O19: اجمالى الاستحقاق | P19: ساعات التاخير | Q19: قيمة ساعات التأخير | R19: سلف | S19: سلفة مرحله | T19: جزاء ادارى | U19: قيمة الجزاء الادارى | V19: جزاء البصمه | W19: قيمة جزاء البصمه | X19: غياب بدون اذن | Y19: جزاء غياب بدون اذن | Z19: المرضى | AA19: قيمة المرضى | AB19: الراتب التاميني | AC19: تأمينات وضرائب | AD19: الانحرافات | AE19: عجز منتجات& عهدة
A20: =+'فرع الزقازيق'!A8 -> 0 | B20: =+'فرع الزقازيق'!B8 -> 0 | C20: =+'فرع الزقازيق'!C8 -> 0 | D20: =+'فرع الزقازيق'!D8 -> 0 | E20: =+'فرع الزقازيق'!E8 -> 0 | F20: =+'فرع الزقازيق'!F8 -> 0 | G20: =+'فرع الزقازيق'!G8 -> 0 | H20: =+'فرع الزقازيق'!H8 -> 0 | ... AH20: =+'فرع الزقازيق'!AH8 -> 0
A22: الكود | B22: الاسم | C22: الفرع | D22: الوظيفة | E22: ساعات العمل | F22: الراتب | G22: الاستحقاق | P22: الاستقطاع | AF22: اجمالى الاستقطاع | AG22: صافى الراتب | AH22: ملاحظات
G23: ايام العمل | H23: قيمة ايام العمل | I23: الاضافى بالساعات | J23: قيمة الاضافى | K23: بدل اجازات | L23: قيمة بدل الاجازات | M23: مكافأة | N23: اخرى | O23: اجمالى الاستحقاق | P23: ساعات التاخير | Q23: قيمة ساعات التأخير | R23: سلف | S23: سلفة مرحله | T23: جزاء ادارى | U23: قيمة الجزاء الادارى | V23: جزاء البصمه | W23: قيمة جزاء البصمه | X23: غياب بدون اذن | Y23: جزاء غياب بدون اذن | Z23: المرضى | AA23: قيمة المرضى | AB23: الراتب التاميني | AC23: تأمينات وضرائب | AD23: الانحرافات | AE23: عجز منتجات& عهدة
A24: =+'فرع الزقازيق'!A9 -> 0 | B24: =+'فرع الزقازيق'!B9 -> 0 | C24: =+'فرع الزقازيق'!C9 -> 0 | D24: =+'فرع الزقازيق'!D9 -> 0 | E24: =+'فرع الزقازيق'!E9 -> 0 | F24: =+'فرع الزقازيق'!F9 -> 0 | G24: =+'فرع الزقازيق'!G9 -> 0 | H24: =+'فرع الزقازيق'!H9 -> 0 | ... AH24: =+'فرع الزقازيق'!AH9 -> 0
A26: الكود | B26: الاسم | C26: الفرع | D26: الوظيفة | E26: ساعات العمل | F26: الراتب | G26: الاستحقاق | P26: الاستقطاع | AF26: اجمالى الاستقطاع | AG26: صافى الراتب | AH26: ملاحظات
G27: ايام العمل | H27: قيمة ايام العمل | I27: الاضافى بالساعات | J27: قيمة الاضافى | K27: بدل اجازات | L27: قيمة بدل الاجازات | M27: مكافأة | N27: اخرى | O27: اجمالى الاستحقاق | P27: ساعات التاخير | Q27: قيمة ساعات التأخير | R27: سلف | S27: سلفة مرحله | T27: جزاء ادارى | U27: قيمة الجزاء الادارى | V27: جزاء البصمه | W27: قيمة جزاء البصمه | X27: غياب بدون اذن | Y27: جزاء غياب بدون اذن | Z27: المرضى | AA27: قيمة المرضى | AB27: الراتب التاميني | AC27: تأمينات وضرائب | AD27: الانحرافات | AE27: عجز منتجات& عهدة
A28: =+'فرع الزقازيق'!A10 -> 0 | B28: =+'فرع الزقازيق'!B10 -> 0 | C28: =+'فرع الزقازيق'!C10 -> 0 | D28: =+'فرع الزقازيق'!D10 -> 0 | E28: =+'فرع الزقازيق'!E10 -> 0 | F28: =+'فرع الزقازيق'!F10 -> 0 | G28: =+'فرع الزقازيق'!G10 -> 0 | H28: =+'فرع الزقازيق'!H10 -> 0 | ... AH28: =+'فرع الزقازيق'!AH10 -> 0
A30: الكود | B30: الاسم | C30: الفرع | D30: الوظيفة | E30: ساعات العمل | F30: الراتب | G30: الاستحقاق | P30: الاستقطاع | AF30: اجمالى الاستقطاع | AG30: صافى الراتب | AH30: ملاحظات
G31: ايام العمل | H31: قيمة ايام العمل | I31: الاضافى بالساعات | J31: قيمة الاضافى | K31: بدل اجازات | L31: قيمة بدل الاجازات | M31: مكافأة | N31: اخرى | O31: اجمالى الاستحقاق | P31: ساعات التاخير | Q31: قيمة ساعات التأخير | R31: سلف | S31: سلفة مرحله | T31: جزاء ادارى | U31: قيمة الجزاء الادارى | V31: جزاء البصمه | W31: قيمة جزاء البصمه | X31: غياب بدون اذن | Y31: جزاء غياب بدون اذن | Z31: المرضى | AA31: قيمة المرضى | AB31: الراتب التاميني | AC31: تأمينات وضرائب | AD31: الانحرافات | AE31: عجز منتجات& عهدة
A32: =+'فرع الزقازيق'!A11 -> 0 | B32: =+'فرع الزقازيق'!B11 -> 0 | C32: =+'فرع الزقازيق'!C11 -> 0 | D32: =+'فرع الزقازيق'!D11 -> 0 | E32: =+'فرع الزقازيق'!E11 -> 0 | F32: =+'فرع الزقازيق'!F11 -> 0 | G32: =+'فرع الزقازيق'!G11 -> 0 | H32: =+'فرع الزقازيق'!H11 -> 0 | ... AH32: =+'فرع الزقازيق'!AH11 -> 0
A34: الكود | B34: الاسم | C34: الفرع | D34: الوظيفة | E34: ساعات العمل | F34: الراتب | G34: الاستحقاق | P34: الاستقطاع | AF34: اجمالى الاستقطاع | AG34: صافى الراتب | AH34: ملاحظات
G35: ايام العمل | H35: قيمة ايام العمل | I35: الاضافى بالساعات | J35: قيمة الاضافى | K35: بدل اجازات | L35: قيمة بدل الاجازات | M35: مكافأة | N35: اخرى | O35: اجمالى الاستحقاق | P35: ساعات التاخير | Q35: قيمة ساعات التأخير | R35: سلف | S35: سلفة مرحله | T35: جزاء ادارى | U35: قيمة الجزاء الادارى | V35: جزاء البصمه | W35: قيمة جزاء البصمه | X35: غياب بدون اذن | Y35: جزاء غياب بدون اذن | Z35: المرضى | AA35: قيمة المرضى | AB35: الراتب التاميني | AC35: تأمينات وضرائب | AD35: الانحرافات | AE35: عجز منتجات& عهدة
A36: =+'فرع الزقازيق'!A12 -> 0 | B36: =+'فرع الزقازيق'!B12 -> 0 | C36: =+'فرع الزقازيق'!C12 -> 0 | D36: =+'فرع الزقازيق'!D12 -> 0 | E36: =+'فرع الزقازيق'!E12 -> 0 | F36: =+'فرع الزقازيق'!F12 -> 0 | G36: =+'فرع الزقازيق'!G12 -> 0 | H36: =+'فرع الزقازيق'!H12 -> 0 | ... AH36: =+'فرع الزقازيق'!AH12 -> 0
A38: الكود | B38: الاسم | C38: الفرع | D38: الوظيفة | E38: ساعات العمل | F38: الراتب | G38: الاستحقاق | P38: الاستقطاع | AF38: اجمالى الاستقطاع | AG38: صافى الراتب | AH38: ملاحظات
G39: ايام العمل | H39: قيمة ايام العمل | I39: الاضافى بالساعات | J39: قيمة الاضافى | K39: بدل اجازات | L39: قيمة بدل الاجازات | M39: مكافأة | N39: اخرى | O39: اجمالى الاستحقاق | P39: ساعات التاخير | Q39: قيمة ساعات التأخير | R39: سلف | S39: سلفة مرحله | T39: جزاء ادارى | U39: قيمة الجزاء الادارى | V39: جزاء البصمه | W39: قيمة جزاء البصمه | X39: غياب بدون اذن | Y39: جزاء غياب بدون اذن | Z39: المرضى | AA39: قيمة المرضى | AB39: الراتب التاميني | AC39: تأمينات وضرائب | AD39: الانحرافات | AE39: عجز منتجات& عهدة
A40: =+'فرع الزقازيق'!A13 -> 0 | B40: =+'فرع الزقازيق'!B13 -> 0 | C40: =+'فرع الزقازيق'!C13 -> 0 | D40: =+'فرع الزقازيق'!D13 -> 0 | E40: =+'فرع الزقازيق'!E13 -> 0 | F40: =+'فرع الزقازيق'!F13 -> 0 | G40: =+'فرع الزقازيق'!G13 -> 0 | H40: =+'فرع الزقازيق'!H13 -> 0 | ... AH40: =+'فرع الزقازيق'!AH13 -> 0
A42: الكود | B42: الاسم | C42: الفرع | D42: الوظيفة | E42: ساعات العمل | F42: الراتب | G42: الاستحقاق | P42: الاستقطاع | AF42: اجمالى الاستقطاع | AG42: صافى الراتب | AH42: ملاحظات
G43: ايام العمل | H43: قيمة ايام العمل | I43: الاضافى بالساعات | J43: قيمة الاضافى | K43: بدل اجازات | L43: قيمة بدل الاجازات | M43: مكافأة | N43: اخرى | O43: اجمالى الاستحقاق | P43: ساعات التاخير | Q43: قيمة ساعات التأخير | R43: سلف | S43: سلفة مرحله | T43: جزاء ادارى | U43: قيمة الجزاء الادارى | V43: جزاء البصمه | W43: قيمة جزاء البصمه | X43: غياب بدون اذن | Y43: جزاء غياب بدون اذن | Z43: المرضى | AA43: قيمة المرضى | AB43: الراتب التاميني | AC43: تأمينات وضرائب | AD43: الانحرافات | AE43: عجز منتجات& عهدة
A44: =+'فرع الزقازيق'!A14 -> 0 | B44: =+'فرع الزقازيق'!B14 -> 0 | C44: =+'فرع الزقازيق'!C14 -> 0 | D44: =+'فرع الزقازيق'!D14 -> 0 | E44: =+'فرع الزقازيق'!E14 -> 0 | F44: =+'فرع الزقازيق'!F14 -> 0 | G44: =+'فرع الزقازيق'!G14 -> 0 | H44: =+'فرع الزقازيق'!H14 -> 0 | ... AH44: =+'فرع الزقازيق'!AH14 -> 0
A46: الكود | B46: الاسم | C46: الفرع | D46: الوظيفة | E46: ساعات العمل | F46: الراتب | G46: الاستحقاق | P46: الاستقطاع | AF46: اجمالى الاستقطاع | AG46: صافى الراتب | AH46: ملاحظات
